2023-01-13 10:09:09,967 ERROR: Exception on /favicon.ico [GET] [in /Users/dennis/microblog/venv/lib/python3.7/site-packages/flask/app.py:1742]
Traceback (most recent call last):
  File "/Users/dennis/microblog/venv/lib/python3.7/site-packages/flask/app.py", line 1820, in full_dispatch_request
    rv = self.dispatch_request()
  File "/Users/dennis/microblog/venv/lib/python3.7/site-packages/flask/app.py", line 1785, in dispatch_request
    self.raise_routing_exception(req)
  File "/Users/dennis/microblog/venv/lib/python3.7/site-packages/flask/app.py", line 1767, in raise_routing_exception
    raise request.routing_exception  # type: ignore
  File "/Users/dennis/microblog/venv/lib/python3.7/site-packages/flask/ctx.py", line 351, in match_request
    result = self.url_adapter.match(return_rule=True)  # type: ignore
  File "/Users/dennis/microblog/venv/lib/python3.7/site-packages/werkzeug/routing/map.py", line 624, in match
    raise NotFound() from None
werkzeug.exceptions.NotFound: 404 Not Found: The requested URL was not found on the server. If you entered the URL manually please check your spelling and try again.

During handling of the above exception, another exception occurred:

Traceback (most recent call last):
  File "/Users/dennis/microblog/venv/lib/python3.7/site-packages/flask/app.py", line 2525, in wsgi_app
    response = self.full_dispatch_request()
  File "/Users/dennis/microblog/venv/lib/python3.7/site-packages/flask/app.py", line 1822, in full_dispatch_request
    rv = self.handle_user_exception(e)
  File "/Users/dennis/microblog/venv/lib/python3.7/site-packages/flask/app.py", line 1666, in handle_user_exception
    return self.handle_http_exception(e)
  File "/Users/dennis/microblog/venv/lib/python3.7/site-packages/flask/app.py", line 1606, in handle_http_exception
    return self.ensure_sync(handler)(e)
  File "/Users/dennis/microblog/app/errors/handlers.py", line 8, in not_found_error
    return render_template('errors/404.html'), 404
  File "/Users/dennis/microblog/venv/lib/python3.7/site-packages/flask/templating.py", line 147, in render_template
    return _render(app, template, context)
  File "/Users/dennis/microblog/venv/lib/python3.7/site-packages/flask/templating.py", line 130, in _render
    rv = template.render(context)
  File "/Users/dennis/microblog/venv/lib/python3.7/site-packages/jinja2/environment.py", line 1301, in render
    self.environment.handle_exception()
  File "/Users/dennis/microblog/venv/lib/python3.7/site-packages/jinja2/environment.py", line 936, in handle_exception
    raise rewrite_traceback_stack(source=source)
  File "/Users/dennis/microblog/app/templates/errors/404.html", line 1, in top-level template code
    {% extends "base.html" %}
  File "/Users/dennis/microblog/app/templates/base.html", line 1, in top-level template code
    {% extends 'bootstrap/base.html' %}
  File "/Users/dennis/microblog/venv/lib/python3.7/site-packages/flask_bootstrap/templates/bootstrap/base.html", line 1, in top-level template code
    {% block doc -%}
  File "/Users/dennis/microblog/venv/lib/python3.7/site-packages/flask_bootstrap/templates/bootstrap/base.html", line 4, in block 'doc'
    {%- block html %}
  File "/Users/dennis/microblog/venv/lib/python3.7/site-packages/flask_bootstrap/templates/bootstrap/base.html", line 20, in block 'html'
    {% block body -%}
  File "/Users/dennis/microblog/venv/lib/python3.7/site-packages/flask_bootstrap/templates/bootstrap/base.html", line 23, in block 'body'
    {% block content -%}
  File "/Users/dennis/microblog/app/templates/base.html", line 48, in block 'content'
    {% block app_content %}{% endblock %}
  File "/Users/dennis/microblog/app/templates/errors/404.html", line 5, in block 'app_content'
    <p><a href="{{ url_for('index') }}">Back</a></p>
  File "/Users/dennis/microblog/venv/lib/python3.7/site-packages/flask/app.py", line 2031, in url_for
    return self.handle_url_build_error(error, endpoint, values)
  File "/Users/dennis/microblog/venv/lib/python3.7/site-packages/flask/app.py", line 2025, in url_for
    force_external=_external,
  File "/Users/dennis/microblog/venv/lib/python3.7/site-packages/werkzeug/routing/map.py", line 917, in build
    raise BuildError(endpoint, values, method, self)
werkzeug.routing.exceptions.BuildError: Could not build url for endpoint 'index'. Did you mean 'main.index' instead?
